Workbook
Name 明细分类账: #REF!
Name 明细分类账: #REF!

Sheet 财务报表汇总表
B2: 一、本届期初期末资产负债总体变动情况
B3: 会计科目 | C3: =#REF! -> #REF! | D3: =#REF! -> #REF! | G3: 项 目 | H3: 本届期初余额 | I3: 本届期末余额 | J3: 本届变动余额 | L3: 项 目 | M3: 本届期初余额 | N3: 本届期末余额 | O3: 本届变动余额
B4: 会计科目 | C4: 本届期初余额 | D4: 本届期末余额 | E4: 本届变动额 | G4: 货币资金 | H4: 1318629.2 | I4: 1327697.1 | J4: 9067.84 | L4: 货币资金 | M4: 1318629.2 | N4: 1327697.1 | O4: 9067.84 | Q4: =N4-M4-O4 -> 8.3673513e-11
B5: 资产总额 | C5: =#REF! -> #REF! | D5: =#REF! -> #REF! | E5: =D5-C5 -> #REF! | G5: 应收款项 | H5: 3000 | I5: 0 | J5: -3000 | L5: 应收款项 | M5: 3000 | N5: 0 | O5: -3000 | Q5: =N5-M5-O5 -> 0
B6: 负债总额 | C6: =#REF! -> #REF! | D6: =#REF! -> #REF! | E6: =D6-C6 -> #REF! | G6: 固定资产净值 | H6: 63356.42 | I6: 10881.52 | J6: -52474.9 | L6: 固定资产净值 | M6: 63356.42 | N6: 10881.52 | O6: -52474.9 | Q6: =N6-M6-O6 -> 0
B7: 净资产总额 | C7: =#REF! -> #REF! | D7: =#REF! -> #REF! | E7: =D7-C7 -> #REF! | G7: 资产总额合计 | H7: 1386329.6 | I7: 1338578.6 | J7: -47751.06 | L7: 资产总额合计 | M7: 1386329.6 | N7: 1338578.6 | O7: -46407.06 | Q7: =N7-M7 -> -47751.06
H8: =H6+H5+H4 -> 1384985.6 | I8: =I6+I5+I4 -> 1338578.6 | J8: =J6+J5+J4 -> -46407.06 | M8: =M6+M5+M4 -> 1384985.6 | N8: =N6+N5+N4 -> 1338578.6 | O8: =O6+O5+O4 -> -46407.06
B9: （二）本届资产构成及变动情况 | G9: （三）本届负债构成及变动情况 | L9: （三）净资产变动情况
B10: 会计科目 | C10: 本届期初余额 | D10: 本届期末余额 | E10: 本届变动额 | G10: 会计科目 | H10: 本届期初余额 | I10: 本届期末余额 | J10: 本届变动额 | L10: 项 目 | M10: 限定性净资产 | N10: 非限定性净资产 | O10: 合计
B11: =#REF! -> #REF! | C11: =#REF! -> #REF! | D11: =#REF! -> #REF! | E11: =D11-C11 -> #REF! | G11: =#REF! -> #REF! | H11: =#REF! -> #REF! | I11: =#REF! -> #REF! | J11: =I11-H11 -> #REF! | L11: 本届期初余额 | M11: =#REF! -> #REF! | N11: =#REF! -> #REF! | O11: =N11+M11 -> #REF!
B12: =#REF! -> #REF! | C12: =#REF! -> #REF! | D12: =#REF! -> #REF! | E12: =D12-C12 -> #REF! | G12: =#REF! -> #REF! | H12: =#REF! -> #REF! | I12: =#REF! -> #REF! | J12: =I12-H12 -> #REF! | L12: 本届增加
B13: =#REF! -> #REF! | C13: =#REF! -> #REF! | D13: =#REF! -> #REF! | E13: =D13-C13 -> #REF! | G13: =#REF! -> #REF! | H13: =#REF! -> #REF! | I13: =#REF! -> #REF! | J13: =I13-H13 -> #REF! | L13: 本届减少
B14: =#REF! -> #REF! | C14: =#REF! -> #REF! | D14: =#REF! -> #REF! | E14: =D14-C14 -> #REF! | G14: =#REF! -> #REF! | H14: =#REF! -> #REF! | I14: =#REF! -> #REF! | J14: =I14-H14 -> #REF! | L14: 本届期末余额 | M14: =#REF! -> #REF! | N14: =#REF! -> #REF! | O14: =N14+M14 -> #REF!
B15: =#REF! -> #REF! | C15: =#REF! -> #REF! | D15: =#REF! -> #REF! | E15: =D15-C15 -> #REF! | G15: =#REF! -> #REF! | H15: =#REF! -> #REF! | I15: =#REF! -> #REF! | J15: =I15-H15 -> #REF! | L15: 净资产变动额 | M15: =M14-M11 -> #REF! | N15: =N14-N11 -> #REF! | O15: =O14-O11 -> #REF!
B16: =#REF! -> #REF! | C16: =#REF! -> #REF! | D16: =#REF! -> #REF! | E16: =D16-C16 -> #REF! | G16: =#REF! -> #REF! | H16: =#REF! -> #REF! | I16: =#REF! -> #REF! | J16: =I16-H16 -> #REF!
B17: =#REF! -> #REF! | C17: =#REF! -> #REF! | D17: =#REF! -> #REF! | E17: =D17-C17 -> #REF! | G17: =#REF! -> #REF! | H17: =#REF! -> #REF! | I17: =#REF! -> #REF! | J17: =I17-H17 -> #REF!
B18: =#REF! -> #REF! | C18: =#REF! -> #REF! | D18: =#REF! -> #REF! | E18: =D18-C18 -> #REF! | G18: =#REF! -> #REF! | H18: =#REF! -> #REF! | I18: =#REF! -> #REF! | J18: =I18-H18 -> #REF! | M18: =M7-M8 -> 1344
B19: =#REF! -> #REF! | C19: =#REF! -> #REF! | D19: =#REF! -> #REF! | E19: =D19-C19 -> #REF! | G19: =#REF! -> #REF! | H19: =#REF! -> #REF! | I19: =#REF! -> #REF! | J19: =I19-H19 -> #REF!
B20: =#REF! -> #REF! | C20: =#REF! -> #REF! | D20: =#REF! -> #REF! | E20: =D20-C20 -> #REF! | G20: =#REF! -> #REF! | H20: =#REF! -> #REF! | I20: =#REF! -> #REF! | J20: =I20-H20 -> #REF! | L20: 项 目 | M20: 本届期初余额 | N20: 本届期末余额 | O20: 本届变动余额
B21: =#REF! -> #REF! | C21: =#REF! -> #REF! | D21: =#REF! -> #REF! | E21: =D21-C21 -> #REF! | G21: =#REF! -> #REF! | H21: =#REF! -> #REF! | I21: =#REF! -> #REF! | J21: =I21-H21 -> #REF! | L21: 货币资金 | M21: 1318629.2 | N21: 1327697.1 | O21: 9067.84 | Q21: =N21-M21 -> 9067.84 | R21: =Q21-O21 -> 8.3673513e-11
B22: =#REF! -> #REF! | C22: =#REF! -> #REF! | D22: =#REF! -> #REF! | E22: =D22-C22 -> #REF! | G22: 18328 | H22: =#REF! -> #REF! | I22: =#REF! -> #REF! | J22: =I22-H22 -> #REF! | L22: 应收款项 | M22: 3000 | N22: 0 | O22: -3000 | Q22: =N22-M22 -> -3000 | R22: =Q22-O22 -> 0
B23: =#REF! -> #REF! | C23: =#REF! -> #REF! | D23: =#REF! -> #REF! | E23: =D23-C23 -> #REF! | G23: =#REF! -> #REF! | H23: =#REF! -> #REF! | I23: =#REF! -> #REF! | J23: =I23-H23 -> #REF! | L23: 固定资产净值 | M23: 63356.42 | N23: 10881.52 | O23: -52474.9 | Q23: =N23-M23 -> -52474.9 | R23: =Q23-O23 -> 0
B24: =#REF! -> #REF! | C24: =#REF! -> #REF! | D24: =#REF! -> #REF! | E24: =D24-C24 -> #REF! | G24: =#REF! -> #REF! | H24: =#REF! -> #REF! | I24: =#REF! -> #REF! | J24: =I24-H24 -> #REF! | L24: 资产总额合计 | M24: 1384985.6 | N24: 1338578.6 | O24: -46407.06 | Q24: =N24-M24 -> -46407.06 | R24: =Q24-O24 -> 1.7462298e-10
B25: =#REF! -> #REF! | C25: =#REF! -> #REF! | D25: =#REF! -> #REF! | E25: =D25-C25 -> #REF! | G25: =#REF! -> #REF! | H25: =#REF! -> #REF! | I25: =#REF! -> #REF! | J25: =I25-H25 -> #REF!
B26: =#REF! -> #REF! | C26: =#REF! -> #REF! | D26: =#REF! -> #REF! | E26: =D26-C26 -> #REF! | G26: =#REF! -> #REF! | H26: =#REF! -> #REF! | I26: =#REF! -> #REF! | J26: =I26-H26 -> #REF! | M26: =SUM((M21:M23)) -> 1384985.6 | N26: =SUM((N21:N23)) -> 1338578.6 | O26: =SUM((O21:O23)) -> -46407.06 | Q26: =N26-M26 -> -46407.06 | R26: =Q26-O26 -> 1.7462298e-10
B27: =#REF! -> #REF! | C27: =#REF! -> #REF! | D27: =#REF! -> #REF! | E27: =D27-C27 -> #REF! | G27: =#REF! -> #REF! | H27: =#REF! -> #REF! | I27: =#REF! -> #REF! | J27: =I27-H27 -> #REF!
B28: =#REF! -> #REF! | C28: =#REF! -> #REF! | D28: =#REF! -> #REF! | E28: =D28-C28 -> #REF!
B29: =#REF! -> #REF! | C29: =#REF! -> #REF! | D29: =#REF! -> #REF! | E29: =D29-C29 -> #REF!
B30: =#REF! -> #REF! | C30: =#REF! -> #REF! | D30: =#REF! -> #REF! | E30: =D30-C30 -> #REF!
C31: =C11+C13+C24 -> #REF! | D31: =D11+D13+D24 -> #REF! | E31: =E11+E13+E24 -> #REF!
B32: 四、收支结余表（收入）
B33: 年份 | C33: =#REF! -> #REF! | D33: =#REF! -> #REF! | E33: =#REF! -> #REF! | F33: =#REF! -> #REF! | G33: =#REF! -> #REF! | H33: =#REF! -> #REF! | I33: 合计 | J33: 核对合计 | K33: 校验
B34: =#REF! -> #REF! | C34: =#REF! -> #REF! | D34: =#REF! -> #REF! | E34: =#REF! -> #REF! | F34: =#REF! -> #REF! | G34: =#REF! -> #REF! | H34: =#REF! -> #REF! | I34: =#REF! -> #REF! | J34: =SUM(C34:H34) -> #REF! | K34: =J34-I34 -> #REF!
B35: =#REF! -> #REF! | C35: =#REF! -> #REF! | D35: =#REF! -> #REF! | E35: =#REF! -> #REF! | F35: =#REF! -> #REF! | G35: =#REF! -> #REF! | H35: =#REF! -> #REF! | I35: =#REF! -> #REF! | J35: =SUM(C35:H35) -> #REF! | K35: =J35-I35 -> #REF!
B36: =#REF! -> #REF! | C36: =#REF! -> #REF! | D36: =#REF! -> #REF! | E36: =#REF! -> #REF! | F36: =#REF! -> #REF! | G36: =#REF! -> #REF! | H36: =#REF! -> #REF! | I36: =#REF! -> #REF! | J36: =SUM(C36:H36) -> #REF! | K36: =J36-I36 -> #REF!
B37: =#REF! -> #REF! | C37: =#REF! -> #REF! | D37: =#REF! -> #REF! | E37: =#REF! -> #REF! | F37: =#REF! -> #REF! | G37: =#REF! -> #REF! | H37: =#REF! -> #REF! | I37: =#REF! -> #REF! | J37: =SUM(C37:H37) -> #REF! | K37: =J37-I37 -> #REF!
B38: =#REF! -> #REF! | C38: =#REF! -> #REF! | D38: =#REF! -> #REF! | E38: =#REF! -> #REF! | F38: =#REF! -> #REF! | G38: =#REF! -> #REF! | H38: =#REF! -> #REF! | I38: =#REF! -> #REF! | J38: =SUM(C38:H38) -> #REF! | K38: =J38-I38 -> #REF!
B39: ='2024业务活动表'!D4 -> 2024年累计数 | C39: ='2024业务活动表'!D6 -> 0 | D39: ='2024业务活动表'!D7 -> 275000 | E39: ='2024业务活动表'!D8 -> 0 | F39: ='2024业务活动表'!D9 -> 0 | G39: ='2024业务活动表'!D10 -> 0 | H39: ='2024业务活动表'!D10 -> 0 | I39: ='2024业务活动表'!D12 -> 277209.63 | J39: =SUM(C39:H39) -> 275000 | K39: =J39-I39 -> -2209.63
B40: =#REF! -> #REF! | C40: =#REF! -> #REF! | D40: =#REF! -> #REF! | E40: =#REF! -> #REF! | F40: =#REF! -> #REF! | G40: =#REF! -> #REF! | H40: =#REF! -> #REF! | I40: =#REF! -> #REF! | J40: =SUM(C40:H40) -> #REF! | K40: =J40-I40 -> #REF!
B41: 合计 | C41: =SUM(C34:C40) -> #REF! | D41: =SUM(D34:D40) -> #REF! | E41: =SUM(E34:E40) -> #REF! | F41: =SUM(F34:F40) -> #REF! | G41: =SUM(G34:G40) -> #REF! | H41: =SUM(H34:H40) -> #REF! | I41: =SUM(I34:I40) -> #REF! | J41: =SUM(C41:H41) -> #REF! | K41: =J41-I41 -> #REF!
...

Sheet 2017资产负债表
A1: 资产负债表(资产)
C2: 会民非01表
A3: #REF! | C3: 金额单位：元
A4: 资 产 | B4: 42735 | C4: 43100
A5: 流动资产：
A6: 货币资金 | B6: 722383.7 | C6: 816298.8
A7: 短期投资
A8: 应收账款
A9: 预付款项
A10: 其他应收款
A11: 存货
A12: 待摊费用
A13: 一年内到期的非流动资产
A14: 其他流动资产
A15: 流动资产合计 | B15: 722383.7 | C15: 816298.8
A16: 长期投资：
A17: 长期股权投资
A18: 长期债权投资
A19: 长期投资合计
A20: 固定资产
A21: 减：累计折旧
A22: 固定资产净值
A23: 在建工程
A24: 文物文化资产
A25: 固定资产清理
A26: 固定资产合计
A27: 无形资产
... A29: 受托代理资产
A30: 资产总计 | B30: 722383.7 | C30: 816298.8
A32: 法定代表人: 主管会计工作负责人: 会计机构负责人:
A33: 资产负债表(负债及净资产)
C34: 会民非01 表
A35: =A3 -> #REF! | C35: 金额单位：元
A36: 负债及所有者权益 | B36: =B4 -> 42735 | C36: =C4 -> 43100
A37: 流动负债：
A38: 短期借款
A39: 应付款项
A40: 应付工资
A41: 应交税金
A42: 预收款项
...

Sheet 2017业务活动表
A1: 业务活动表
D2: 会民非02表
A3: #REF! | D3: 金额单位：元
A4: 项 目 | B4: 行次 | C4: 2016年累计数 | D4: 2017年累计数
A5: 一、收入 | B5: 1
A6: 其中：捐赠收入 | B6: 2
A7: 会费收入 | B7: 3 | C7: 240000 | D7: 260000
A8: 提供服务收入 | B8: 4
A9: 政府补助收入 | B9: 5
A10: 投资收益 | B10: 6
A11: 其他收入 | B11: 7 | C11: 2316.45 | D11: 2475.45
A12: 收 入 合 计 | B12: 8 | C12: 242316.45 | D12: 262475.45
A13: 二、费用 | B13: 9
A14: （一）业务活动成本 | B14: 10 | C14: 285020 | D14: 158963
A15: （二）管理费用 | B15: 11 | C15: 8415.53 | D15: 9597.35
A16: （三）筹资费用 | B16: 12
A17: （四）其他费用 | B17: 13
A18: 费 用 合 计 | B18: 14 | C18: 293435.53 | D18: 168560.35
A19: 三、收支结余 | B19: 15 | C19: -51119.08 | D19: =D12-D18 -> 93915.1
A20: 四、限定性净资产转为非限定性净资产 | B20: 16
A21: 五、净资产变动额（若为净资产减少额，以“-”号填列） | B21: 17 | C21: -51119.08 | D21: 93915.1

Sheet 2018资产负债表 
A1: 资产负债表(资产)
C2: 会民非01表
A3: #REF! | C3: 金额单位：元
A4: 资 产 | B4: 43100 | C4: 43465
A5: 流动资产：
A6: 货币资金 | B6: 816298.8 | C6: 996924.33
A7: 短期投资
A8: 应收账款
A9: 预付款项
A10: 其他应收款
A11: 存货
A12: 待摊费用
A13: 一年内到期的非流动资产
A14: 其他流动资产
A15: 流动资产合计 | B15: 816298.8 | C15: 996924.33
A16: 长期投资：
A17: 长期股权投资
A18: 长期债权投资
A19: 长期投资合计
A20: 固定资产
A21: 减：累计折旧
A22: 固定资产净值
A23: 在建工程
A24: 文物文化资产
A25: 固定资产清理
A26: 固定资产合计
A27: 无形资产
... A29: 受托代理资产
A30: 资产总计 | B30: 816298.8 | C30: 996924.33
A32: 法定代表人: 主管会计工作负责人: 会计机构负责人:
A33: 资产负债表(负债及净资产)
C34: 会民非01 表
A35: =A3 -> #REF! | C35: 金额单位：元
A36: 负债及所有者权益 | B36: =B4 -> 43100 | C36: =C4 -> 43465
A37: 流动负债：
A38: 短期借款
A39: 应付款项
A40: 应付工资
A41: 应交税金
A42: 预收款项
...

Sheet 2018业务活动表
A1: 业务活动表
D2: 会民非02表
A3: #REF! | D3: 金额单位：元
A4: 项 目 | B4: 行次 | C4: 2017年累计数 | D4: 2018年累计数
A5: 一、收入 | B5: 1
A6: 其中：捐赠收入 | B6: 2
A7: 会费收入 | B7: 3 | C7: 260000 | D7: 315000
A8: 提供服务收入 | B8: 4 | D8: 20000
A9: 政府补助收入 | B9: 5
A10: 投资收益 | B10: 6
A11: 其他收入 | B11: 7 | C11: 2475.45 | D11: 2786.23
A12: 收 入 合 计 | B12: 8 | C12: 262475.45 | D12: 337786.23
A13: 二、费用 | B13: 9
A14: （一）业务活动成本 | B14: 10 | C14: 158963 | D14: 154288.5
A15: （二）管理费用 | B15: 11 | C15: 9597.35 | D15: 2872.2
A16: （三）筹资费用 | B16: 12
A17: （四）其他费用 | B17: 13
A18: 费 用 合 计 | B18: 14 | C18: 168560.35 | D18: 157160.7
A19: 三、收支结余 | B19: 15 | C19: 93915.1 | D19: =D12-D18 -> 180625.53
A20: 四、限定性净资产转为非限定性净资产 | B20: 16
A21: 五、净资产变动额（若为净资产减少额，以“-”号填列） | B21: 17 | C21: 93915.1 | D21: 180625.53

Sheet 2019资产负债表  
A1: 资产负债表(资产)
C2: 会民非01表
A3: #REF! | C3: 金额单位：元
A4: 资 产 | B4: 43465 | C4: 43830
A5: 流动资产：
A6: 货币资金 | B6: 996924.33 | C6: 1099901.1
A7: 短期投资
A8: 应收账款
A9: 预付款项
A10: 其他应收款
A11: 存货
A12: 待摊费用
A13: 一年内到期的非流动资产
A14: 其他流动资产
A15: 流动资产合计 | B15: 996924.33 | C15: 1099901.1
A16: 长期投资：
A17: 长期股权投资
A18: 长期债权投资
A19: 长期投资合计
A20: 固定资产
A21: 减：累计折旧
A22: 固定资产净值
A23: 在建工程
A24: 文物文化资产
A25: 固定资产清理
A26: 固定资产合计
A27: 无形资产
... A29: 受托代理资产
A30: 资产总计 | B30: 996924.33 | C30: 1099901.1
A32: 法定代表人: 主管会计工作负责人: 会计机构负责人:
A33: 资产负债表(负债及净资产)
C34: 会民非01 表
A35: =A3 -> #REF! | C35: 金额单位：元
A36: 负债及所有者权益 | B36: =B4 -> 43465 | C36: =C4 -> 43830
A37: 流动负债：
A38: 短期借款
A39: 应付款项
A40: 应付工资
A41: 应交税金
A42: 预收款项
...

Sheet 2019业务活动表
A1: 业务活动表
D2: 会民非02表
A3: #REF! | D3: 金额单位：元
A4: 项 目 | B4: 行次 | C4: 2018年累计数 | D4: 2019年累计数
A5: 一、收入 | B5: 1
A6: 其中：捐赠收入 | B6: 2
A7: 会费收入 | B7: 3 | C7: 315000 | D7: 290000
A8: 提供服务收入 | B8: 4 | C8: 20000 | D8: 20000
A9: 政府补助收入 | B9: 5
A10: 投资收益 | B10: 6
A11: 其他收入 | B11: 7 | C11: 2786.23 | D11: 3248.65
A12: 收 入 合 计 | B12: 8 | C12: 337786.23 | D12: 313248.65
A13: 二、费用 | B13: 9
A14: （一）业务活动成本 | B14: 10 | C14: 154288.5 | D14: 206836.5
A15: （二）管理费用 | B15: 11 | C15: 2872.2 | D15: 3435.35
A16: （三）筹资费用 | B16: 12
A17: （四）其他费用 | B17: 13
A18: 费 用 合 计 | B18: 14 | C18: 157160.7 | D18: 210271.85
A19: 三、收支结余 | B19: 15 | C19: 180625.53 | D19: =D12-D18 -> 102976.8
A20: 四、限定性净资产转为非限定性净资产 | B20: 16
A21: 五、净资产变动额（若为净资产减少额，以“-”号填列） | B21: 17 | C21: 180625.53 | D21: 102976.8

Sheet 2020资产负债表
A1: 资产负债表(资产)
C2: 会民非01表
A3: #REF! | C3: 金额单位：元
A4: 资 产 | B4: 43830 | C4: 44196
A5: 流动资产：
A6: 货币资金 | B6: 1099901.1 | C6: 1043346.3
A7: 短期投资
A8: 应收账款
A9: 预付款项
A10: 其他应收款
A11: 存货
A12: 待摊费用
A13: 一年内到期的非流动资产
A14: 其他流动资产
A15: 流动资产合计 | B15: 1099901.1 | C15: 1043346.3
A16: 长期投资：
A17: 长期股权投资
A18: 长期债权投资
A19: 长期投资合计
A20: 固定资产
A21: 减：累计折旧
A22: 固定资产净值
A23: 在建工程
A24: 文物文化资产
A25: 固定资产清理
A26: 固定资产合计
A27: 无形资产
... A29: 受托代理资产
A30: 资产总计 | B30: 1099901.1 | C30: 1043346.3
A32: 法定代表人: 主管会计工作负责人: 会计机构负责人:
A33: 资产负债表(负债及净资产)
C34: 会民非01 表
A35: =A3 -> #REF! | C35: 金额单位：元
A36: 负债及所有者权益 | B36: =B4 -> 43830 | C36: =C4 -> 44196
A37: 流动负债：
A38: 短期借款
A39: 应付款项
A40: 应付工资
A41: 应交税金
A42: 预收款项
...

Sheet 2020业务活动表
A1: 业务活动表
D2: 会民非02表
A3: #REF! | D3: 金额单位：元
A4: 项 目 | B4: 行次 | C4: 2019年累计数 | D4: 2020年累计数
A5: 一、收入 | B5: 1
A6: 其中：捐赠收入 | B6: 2
A7: 会费收入 | B7: 3 | C7: 290000 | D7: 60000
A8: 提供服务收入 | B8: 4 | C8: 20000
A9: 政府补助收入 | B9: 5
A10: 投资收益 | B10: 6
A11: 其他收入 | B11: 7 | C11: 3248.65 | D11: 3284.93
A12: 收 入 合 计 | B12: 8 | C12: 313248.65 | D12: 63284.93
A13: 二、费用 | B13: 9
A14: （一）业务活动成本 | B14: 10 | C14: 206836.5 | D14: 114700
A15: （二）管理费用 | B15: 11 | C15: 3435.35 | D15: 5139.8
A16: （三）筹资费用 | B16: 12
A17: （四）其他费用 | B17: 13
A18: 费 用 合 计 | B18: 14 | C18: 210271.85 | D18: 119839.8
A19: 三、收支结余 | B19: 15 | C19: 102976.8 | D19: =D12-D18 -> -56554.87
A20: 四、限定性净资产转为非限定性净资产 | B20: 16
A21: 五、净资产变动额（若为净资产减少额，以“-”号填列） | B21: 17 | C21: 102976.8 | D21: -56554.87

Sheet 2021资产负债表
A1: 资产负债表(资产)
C2: 会民非01表
A3: #REF! | C3: 金额单位：元
A4: 资 产 | B4: 44196 | C4: 44561
A5: 流动资产：
A6: 货币资金 | B6: 1043346.3 | C6: 1365511.7
A7: 短期投资
A8: 应收账款
A9: 预付款项
A10: 其他应收款
A11: 存货
A12: 待摊费用
A13: 一年内到期的非流动资产
A14: 其他流动资产
A15: 流动资产合计 | B15: 1043346.3 | C15: 1365511.7
A16: 长期投资：
A17: 长期股权投资
A18: 长期债权投资
A19: 长期投资合计
A20: 固定资产
A21: 减：累计折旧
A22: 固定资产净值
A23: 在建工程
A24: 文物文化资产
A25: 固定资产清理
A26: 固定资产合计
A27: 无形资产
... A29: 受托代理资产
A30: 资产总计 | B30: 1043346.3 | C30: 1365511.7
A32: 法定代表人: 主管会计工作负责人: 会计机构负责人:
A33: 资产负债表(负债及净资产)
C34: 会民非01 表
A35: =A3 -> #REF! | C35: 金额单位：元
A36: 负债及所有者权益 | B36: =B4 -> 44196 | C36: =C4 -> 44561
A37: 流动负债：
A38: 短期借款
A39: 应付款项
A40: 应付工资
A41: 应交税金
A42: 预收款项
...

Sheet 2021业务活动表
A1: 业务活动表
D2: 会民非02表
A3: #REF! | D3: 金额单位：元
A4: 项 目 | B4: 行次 | C4: 2020年累计数 | D4: 2021年累计数
A5: 一、收入 | B5: 1
A6: 其中：捐赠收入 | B6: 2
A7: 会费收入 | B7: 3 | C7: 60000 | D7: 370000
A8: 提供服务收入 | B8: 4
A9: 政府补助收入 | B9: 5
A10: 投资收益 | B10: 6
A11: 其他收入 | B11: 7 | C11: 3284.93 | D11: 3288.44
A12: 收 入 合 计 | B12: 8 | C12: 63284.93 | D12: 373288.44
A13: 二、费用 | B13: 9
A14: （一）业务活动成本 | B14: 10 | C14: 114700 | D14: 43859
A15: （二）管理费用 | B15: 11 | C15: 5139.8 | D15: 7264
A16: （三）筹资费用 | B16: 12
A17: （四）其他费用 | B17: 13
A18: 费 用 合 计 | B18: 14 | C18: 119839.8 | D18: 51123
A19: 三、收支结余 | B19: 15 | C19: -56554.87 | D19: =D12-D18 -> 322165.44
A20: 四、限定性净资产转为非限定性净资产 | B20: 16
A21: 五、净资产变动额（若为净资产减少额，以“-”号填列） | B21: 17 | C21: -56554.87 | D21: 322165.44

Sheet 2022资产负债表 
A1: 资产负债表(资产)
C2: 会民非01表
A3: =#REF! -> #REF! | C3: 金额单位：元
A4: 资 产 | B4: 44561 | C4: 44926
A5: 流动资产：
A6: 货币资金 | B6: 1365511.7 | C6: 1359033.9
A7: 短期投资
A8: 应收账款
A9: 预付款项
A10: 其他应收款
A11: 存货
A12: 待摊费用
A13: 一年内到期的非流动资产
A14: 其他流动资产
A15: 流动资产合计 | B15: 1365511.7 | C15: 1359033.9
A16: 长期投资：
A17: 长期股权投资
A18: 长期债权投资
A19: 长期投资合计
A20: 固定资产
A21: 减：累计折旧
A22: 固定资产净值
A23: 在建工程
A24: 文物文化资产
A25: 固定资产清理
A26: 固定资产合计
A27: 无形资产
... A29: 受托代理资产
A30: 资产总计 | B30: 1365511.7 | C30: 1359033.9
A32: 法定代表人: 主管会计工作负责人: 会计机构负责人:
A33: 资产负债表(负债及净资产)
C34: 会民非01 表
A35: =A3 -> #REF! | C35: 金额单位：元
A36: 负债及所有者权益 | B36: =B4 -> 44561 | C36: =C4 -> 44926
A37: 流动负债：
A38: 短期借款
A39: 应付款项
A40: 应付工资
A41: 应交税金
A42: 预收款项
...

Sheet 2022业务活动表
A1: 业务活动表
D2: 会民非02表
A3: #REF! | D3: 金额单位：元
A4: 项 目 | B4: 行次 | C4: 2021年累计数 | D4: 2022年累计数
A5: 一、收入 | B5: 1
A6: 其中：捐赠收入 | B6: 2
A7: 会费收入 | B7: 3 | C7: 370000 | D7: 125000
A8: 提供服务收入 | B8: 4
A9: 政府补助收入 | B9: 5
A10: 投资收益 | B10: 6
A11: 其他收入 | B11: 7 | C11: 3288.44 | D11: 3875.21
A12: 收 入 合 计 | B12: 8 | C12: =C11+C7 -> 373288.44 | D12: 128875.21
A13: 二、费用 | B13: 9
A14: （一）业务活动成本 | B14: 10 | C14: 43859 | D14: 91745
A15: （二）管理费用 | B15: 11 | C15: 7264 | D15: 43608
A16: （三）筹资费用 | B16: 12
A17: （四）其他费用 | B17: 13
A18: 费 用 合 计 | B18: 14 | C18: 51123 | D18: 135353
A19: 三、收支结余 | B19: 15 | C19: =C12-C18 -> 322165.44 | D19: =D12-D18 -> -6477.79
A20: 四、限定性净资产转为非限定性净资产 | B20: 16
A21: 五、净资产变动额（若为净资产减少额，以“-”号填列） | B21: 17 | C21: =C19 -> 322165.44 | D21: =D19 -> -6477.79

Sheet 2023资产负债表
A1: 资产负债表(资产)
C2: 会民非01表
A3: #REF! | C3: 金额单位：元
A4: 资 产 | B4: 44926 | C4: 45291
A5: 流动资产：
A6: 货币资金 | B6: 1359033.9 | C6: 1258436.1
A7: 短期投资
A8: 应收账款
A9: 预付款项
A10: 其他应收款
A11: 存货
A12: 待摊费用
A13: 一年内到期的非流动资产
A14: 其他流动资产
A15: 流动资产合计 | B15: 1359033.9 | C15: 1258436.1
A16: 长期投资：
A17: 长期股权投资
A18: 长期债权投资
A19: 长期投资合计
A20: 固定资产
A21: 减：累计折旧
A22: 固定资产净值
A23: 在建工程
A24: 文物文化资产
A25: 固定资产清理
A26: 固定资产合计
A27: 无形资产
... A29: 受托代理资产
A30: 资产总计 | B30: 1359033.9 | C30: 1258436.1
A32: 法定代表人: 主管会计工作负责人: 会计机构负责人:
A33: 资产负债表(负债及净资产)
C34: 会民非01 表
A35: =A3 -> #REF! | C35: 金额单位：元
A36: 负债及所有者权益 | B36: =B4 -> 44926 | C36: =C4 -> 45291
A37: 流动负债：
A38: 短期借款
A39: 应付款项
A40: 应付工资
A41: 应交税金
A42: 预收款项
...

Sheet 2023业务活动表
A1: 业务活动表
D2: 会民非02表
A3: ='2024资产负债表 '!A3 -> #REF! | D3: 金额单位：元
A4: 项 目 | B4: 行次 | C4: 2022年累计数 | D4: 2023年累计数
A5: 一、收入 | B5: 1
A6: 其中：捐赠收入 | B6: 2
A7: 会费收入 | B7: 3 | C7: 125000 | D7: 135000
A8: 提供服务收入 | B8: 4
A9: 政府补助收入 | B9: 5
A10: 投资收益 | B10: 6
A11: 其他收入 | B11: 7 | C11: 3875.21 | D11: 3012.03
A12: 收 入 合 计 | B12: 8 | C12: 128875.21 | D12: 138012.03
A13: 二、费用 | B13: 9
A14: （一）业务活动成本 | B14: 10 | C14: 91745 | D14: 194332.5
A15: （二）管理费用 | B15: 11 | C15: 43608 | D15: 44277.34
A16: （三）筹资费用 | B16: 12
A17: （四）其他费用 | B17: 13
A18: 费 用 合 计 | B18: 14 | C18: 135353 | D18: 238609.84
A19: 三、收支结余 | B19: 15 | C19: -6477.79 | D19: =D12-D18 -> -100597.81
A20: 四、限定性净资产转为非限定性净资产 | B20: 16
A21: 五、净资产变动额（若为净资产减少额，以“-”号填列） | B21: 17 | C21: -6477.79 | D21: -100597.81

Sheet 2024资产负债表 
A1: 资产负债表(资产)
C2: 会民非01表
A3: #REF! | C3: 金额单位：元
A4: 资 产 | B4: 45291 | C4: 45657
A5: 流动资产：
A6: 货币资金 | B6: 1258436.1 | C6: 1247776.4
A7: 短期投资
A8: 应收账款
A9: 预付款项
A10: 其他应收款
A11: 存货
A12: 待摊费用
A13: 一年内到期的非流动资产
A14: 其他流动资产
A15: 流动资产合计 | B15: 1258436.1 | C15: 1247776.4
A16: 长期投资：
A17: 长期股权投资
A18: 长期债权投资
A19: 长期投资合计
A20: 固定资产
A21: 减：累计折旧
A22: 固定资产净值
A23: 在建工程
A24: 文物文化资产
A25: 固定资产清理
A26: 固定资产合计
A27: 无形资产
... A29: 受托代理资产
A30: 资产总计 | B30: 1258436.1 | C30: 1247776.4
A32: 法定代表人: 主管会计工作负责人: 会计机构负责人:
A33: 资产负债表(负债及净资产)
C34: 会民非01 表
A35: #REF! | C35: 金额单位：元
A36: 负债及所有者权益 | B36: 45291 | C36: 45657
A37: 流动负债：
A38: 短期借款
A39: 应付款项
A40: 应付工资
A41: 应交税金
A42: 预收款项
...

Sheet 2024业务活动表
A1: 业务活动表
D2: 会民非02表
A3: #REF! | D3: 金额单位：元
A4: 项 目 | B4: 行次 | C4: 2023年累计数 | D4: 2024年累计数
A5: 一、收入 | B5: 1
A6: 其中：捐赠收入 | B6: 2
A7: 会费收入 | B7: 3 | C7: 135000 | D7: 275000
A8: 提供服务收入 | B8: 4
A9: 政府补助收入 | B9: 5
A10: 投资收益 | B10: 6
A11: 其他收入 | B11: 7 | C11: 3012.03 | D11: 2209.63
A12: 收 入 合 计 | B12: 8 | C12: 138012.03 | D12: 277209.63
A13: 二、费用 | B13: 9
A14: （一）业务活动成本 | B14: 10 | C14: 194332.5 | D14: 243684.8
A15: （二）管理费用 | B15: 11 | C15: 44277.34 | D15: 44184.5
A16: （三）筹资费用 | B16: 12
A17: （四）其他费用 | B17: 13
A18: 费 用 合 计 | B18: 14 | C18: 238609.84 | D18: 287869.3
A19: 三、收支结余 | B19: 15 | C19: -100597.81 | D19: =D12-D18 -> -10659.67
A20: 四、限定性净资产转为非限定性净资产 | B20: 16
A21: 五、净资产变动额（若为净资产减少额，以“-”号填列） | B21: 17 | C21: -100597.81 | D21: -10659.67

Sheet 2025资产负债表
A1: 资产负债表(资产)
C2: 会民非01表
A3: #REF! | C3: 金额单位：元
A4: 资 产 | B4: 45657 | C4: 45747
A5: 流动资产：
A6: 货币资金 | B6: 1247776.4 | C6: 1113196.6
A7: 短期投资
A8: 应收账款
A9: 预付款项
A10: 其他应收款
A11: 存货
A12: 待摊费用
A13: 一年内到期的非流动资产
A14: 其他流动资产
A15: 流动资产合计 | B15: 1247776.4 | C15: 1113196.6
A16: 长期投资：
A17: 长期股权投资
A18: 长期债权投资
A19: 长期投资合计
A20: 固定资产
A21: 减：累计折旧
A22: 固定资产净值
A23: 在建工程
A24: 文物文化资产
A25: 固定资产清理
A26: 固定资产合计
A27: 无形资产
... A29: 受托代理资产
A30: 资产总计 | B30: 1247776.4 | C30: 1113196.6
A32: 法定代表人: 主管会计工作负责人: 会计机构负责人:
A33: 资产负债表(负债及净资产)
C34: 会民非01 表
A35: =A3 -> #REF! | C35: 金额单位：元
A36: 负债及所有者权益 | B36: =B4 -> 45657 | C36: =C4 -> 45747
A37: 流动负债：
A38: 短期借款
A39: 应付款项
A40: 应付工资
A41: 应交税金
A42: 预收款项
...

Sheet 2025业务活动表
A1: 业务活动表
D2: 会民非02表
A3: #REF! | D3: 金额单位：元
A4: 项 目 | B4: 行次 | C4: 2024年累计数 | D4: 2025年1-3月累计数
A5: 一、收入 | B5: 1
A6: 其中：捐赠收入 | B6: 2
A7: 会费收入 | B7: 3 | C7: 275000
A8: 提供服务收入 | B8: 4
A9: 政府补助收入 | B9: 5
A10: 投资收益 | B10: 6
A11: 其他收入 | B11: 7 | C11: 2209.63 | D11: 292.62
A12: 收 入 合 计 | B12: 8 | C12: 277209.63 | D12: 292.62
A13: 二、费用 | B13: 9
A14: （一）业务活动成本 | B14: 10 | C14: 243684.8 | D14: 32180
A15: （二）管理费用 | B15: 11 | C15: 44184.5 | D15: 102692.5
A16: （三）筹资费用 | B16: 12
A17: （四）其他费用 | B17: 13
A18: 费 用 合 计 | B18: 14 | C18: 287869.3 | D18: 134872.5
A19: 三、收支结余 | B19: 15 | C19: -10659.67 | D19: =D12-D18 -> -134579.88
A20: 四、限定性净资产转为非限定性净资产 | B20: 16
A21: 五、净资产变动额（若为净资产减少额，以“-”号填列） | B21: 17 | C21: -10659.67 | D21: -134579.88

Sheet 母公司所有者权益变动表(有限责任公司) 
A1: 所有者权益变动表 | O1: 注：被审计单位不存在使用蓝色部分科目的，应当删除
N2: 会企04表
A3: =#REF! -> #REF! | N3: 单位：人民币元
A4: 项 目 | B4: =#REF! -> #REF!
B5: 实收资本 | C5: 其他权益工具 | G5: 资本公积 | H5: 减：库存股 | I5: 其他综合收益 | J5: 专项储备 | K5: 盈余公积 | L5: 一般风险准备 | M5: 未分配利润 | N5: 所有者权益合计
C6: 优先股 | D6: 永续债 | E6: 其他 | F6: 小计
A7: 一、上年年末余额 | B7: =B72 -> 0 | C7: =C72 -> 0 | D7: =D72 -> 0 | E7: =E72 -> 0 | F7: =SUM(C7:E7) -> 0 | G7: =G72 -> 0 | H7: =H72 -> 0 | I7: =I72 -> #REF! | J7: =J72 -> 0 | K7: =K72 -> 0 | L7: =L72 -> 0 | M7: =M72 -> #REF! | N7: =SUM(B7,F7:G7,I7:M7)-H7 -> #REF!
A8: 加：会计政策变更 | F8: =SUM(C8:E8) -> 0 | N8: =SUM(B8,F8:G8,I8:M8)-H8 -> 0
A9: 前期差错更正 | F9: =SUM(C9:E9) -> 0 | N9: =SUM(B9,F9:G9,I9:M9)-H9 -> 0
A10: 其他 | F10: =SUM(C10:E10) -> 0 | N10: =SUM(B10,F10:G10,I10:M10)-H10 -> 0
A11: 二、本年年初余额 | B11: =B7+B8+B9 -> 0 | C11: =C7+C8+C9 -> 0 | D11: =D7+D8+D9 -> 0 | E11: =E7+E8+E9 -> 0 | F11: =F7+F8+F9 -> 0 | G11: =G7+G8+G9 -> 0 | H11: =H7+H8+H9 -> 0 | I11: =I7+I8+I9 -> #REF! | ... M11: =M7+M8+M9 -> #REF! | N11: =SUM(B11,F11:G11,I11:M11)-H11 -> #REF!
A12: 三、本年增减变动金额（减少以“-”号填列） | B12: =SUM(B13:B14,B19,B24,B30,B33) -> 0 | C12: =SUM(C13:C14,C19,C24,C30,C33) -> 0 | D12: =SUM(D13:D14,D19,D24,D30,D33) -> 0 | E12: =SUM(E13:E14,E19,E24,E30,E33) -> 0 | F12: =SUM(F13:F14,F19,F24,F30,F33) -> 0 | G12: =SUM(G13:G14,G19,G24,G30,G33) -> 0 | H12: =SUM(H13:H14,H19,H24,H30,H33) -> 0 | I12: =SUM(I13:I14,I19,I24,I30,I33) -> #REF! | ... M12: =SUM(M13:M14,M19,M24,M30,M33) -> #REF! | N12: =SUM(B12,F12:G12,I12:M12)-H12 -> #REF!
A13: （一）综合收益总额 | I13: =#REF! -> #REF! | M13: =#REF! -> #REF! | N13: =SUM(B13,F13:G13,I13:M13)-H13 -> #REF!
A14: （二）所有者投入和减少资本 | B14: =SUM(B15:B18) -> 0 | C14: =SUM(C15:C18) -> 0 | D14: =SUM(D15:D18) -> 0 | E14: =SUM(E15:E18) -> 0 | F14: =SUM(F15:F18) -> 0 | G14: =SUM(G15:G18) -> 0 | H14: =SUM(H15:H18) -> 0 | I14: =SUM(I15:I18) -> 0 | ... M14: =SUM(M15:M18) -> 0 | N14: =SUM(B14,F14:G14,I14:M14)-H14 -> 0
A15: 1. 所有者投入资本 | F15: =SUM(C15:E15) -> 0 | N15: =SUM(B15,F15:G15,I15:M15)-H15 -> 0
A16: 2. 其他权益工具持有者投入资本 | F16: =SUM(C16:E16) -> 0 | N16: =SUM(B16,F16:G16,I16:M16)-H16 -> 0
A17: 3. 股份支付计入所有者权益的金额 | F17: =SUM(C17:E17) -> 0 | N17: =SUM(B17,F17:G17,I17:M17)-H17 -> 0
A18: 4. 其他 | F18: =SUM(C18:E18) -> 0 | N18: =SUM(B18,F18:G18,I18:M18)-H18 -> 0
A19: （三）利润分配 | B19: =SUM(B20:B23) -> 0 | C19: =SUM(C20:C23) -> 0 | D19: =SUM(D20:D23) -> 0 | E19: =SUM(E20:E23) -> 0 | F19: =SUM(F20:F23) -> 0 | G19: =SUM(G20:G23) -> 0 | H19: =SUM(H20:H23) -> 0 | I19: =SUM(I20:I23) -> 0 | ... M19: =SUM(M20:M23) -> 0 | N19: =SUM(B19,F19:G19,I19:M19)-H19 -> 0
A20: 1. 提取盈余公积 | F20: =SUM(C20:E20) -> 0 | M20: =-K20 -> 0 | N20: =SUM(B20,F20:G20,I20:M20)-H20 -> 0
A21: 2. 提取一般风险准备 | F21: =SUM(C21:E21) -> 0 | N21: =SUM(B21,F21:G21,I21:M21)-H21 -> 0
A22: 3.对所有者的分配 | F22: =SUM(C22:E22) -> 0 | N22: =SUM(B22,F22:G22,I22:M22)-H22 -> 0
A23: 4. 其他 | F23: =SUM(C23:E23) -> 0 | N23: =SUM(B23,F23:G23,I23:M23)-H23 -> 0
A24: （四）所有者权益内部结转 | B24: =SUM(B25:B29) -> 0 | C24: =SUM(C25:C29) -> 0 | D24: =SUM(D25:D29) -> 0 | E24: =SUM(E25:E29) -> 0 | F24: =SUM(F25:F29) -> 0 | G24: =SUM(G25:G29) -> 0 | H24: =SUM(H25:H29) -> 0 | I24: =SUM(I25:I29) -> 0 | ... M24: =SUM(M25:M29) -> 0 | N24: =SUM(B24,F24:G24,I24:M24)-H24 -> 0
A25: 1. 资本公积转增资本 | F25: =SUM(C25:E25) -> 0 | G25: =-B25 -> 0 | N25: =SUM(B25,F25:G25,I25:M25)-H25 -> 0
A26: 2. 盈余公积转增资本 | F26: =SUM(C26:E26) -> 0 | N26: =SUM(B26,F26:G26,I26:M26)-H26 -> 0
A27: 3. 盈余公积弥补亏损 | F27: =SUM(C27:E27) -> 0 | N27: =SUM(B27,F27:G27,I27:M27)-H27 -> 0
A28: 4.设定受益计划变动额结转留存收益 | F28: =SUM(C28:E28) -> 0 | N28: =SUM(B28,F28:G28,I28:M28)-H28 -> 0
A29: 5. 其他 | F29: =SUM(C29:E29) -> 0 | N29: =SUM(B29,F29:G29,I29:M29)-H29 -> 0
A30: （五）专项储备 | J30: =J31+J32 -> 0 | N30: =SUM(B30,F30:G30,I30:M30)-H30 -> 0
A31: 1. 本期提取 | N31: =SUM(B31,F31:G31,I31:M31)-H31 -> 0
A32: 2. 本期使用 | N32: =SUM(B32,F32:G32,I32:M32)-H32 -> 0
A33: （六）其他 | N33: =SUM(B33,F33:G33,I33:M33)-H33 -> 0
A34: 四、本年年末余额 | B34: =B11+B12 -> 0 | C34: =C11+C12 -> 0 | D34: =D11+D12 -> 0 | E34: =E11+E12 -> 0 | F34: =F11+F12 -> 0 | G34: =G11+G12 -> 0 | H34: =H11+H12 -> 0 | I34: =I11+I12 -> #REF! | ... M34: =M11+M12 -> #REF! | N34: =SUM(B34,F34:G34,I34:M34)-H34 -> #REF!
A36: 法定代表人: 主管会计工作负责人： 会计机构负责人：
A39: =A1 -> 所有者权益变动表
N40: 会企04表
A41: =A3 -> #REF! | N41: 单位：人民币元
A42: 项 目 | B42: =#REF! -> #REF!
B43: =B5 -> 实收资本 | C43: =C5 -> 其他权益工具 | G43: 资本公积 | H43: 减：库存股 | I43: =I5 -> 其他综合收益 | J43: =J5 -> 专项储备 | K43: =K5 -> 盈余公积 | L43: =L5 -> 一般风险准备 | M43: =M5 -> 未分配利润 | N43: =N5 -> 所有者权益合计
...
